export const retryOperation = async <T>(
  operation: () => Promise<T>,
  maxRetries: number = 3,
  delay: number = 2000
): Promise<T> => {
  for (let attempt = 1; attempt <= maxRetries; attempt++) {
    try {
      return await operation();
    } catch (error) {
      if (attempt === maxRetries) {
        throw error;
      }
      
      console.log(`ðŸ”„ Intento ${attempt} de ${maxRetries} fallÃ³, reintentando en ${delay/1000}s...`);
      await new Promise(resolve => setTimeout(resolve, delay));
    }
  }
  
  // Esta lÃ­nea nunca se ejecutarÃ¡ debido al throw en el catch,
  // pero TypeScript necesita un return aquÃ­
  throw new Error('MÃ¡ximo nÃºmero de intentos alcanzado');
};

export const isNetworkError = (error: Error): boolean => {
  return (
    error.message.includes('NetworkError') ||
    error.message.includes('Failed to fetch') ||
    error.message.includes('Network request failed')
  );
}; 